Workbook

Sheet PrimerSimulacro
E2: Resultados Primer Simulacro | O2: Puntaje por área (0–100)
A3: Grupo | B3: Sexo | C3: Documento | D3: ESTUDIANTES | E3: Enlace Imagen | F3: PDF | G3: Matemática | H3: Ciencias Naturales | I3: Sociales y Ciudadanas | J3: Lectura Crítica | K3: Inglés | L3: Posición dentro del grado | M3: ="Posición dentro de décimo y undécimo ("&(COUNTIFS(Comparativosimulacros!$C$4:$C$1500,">=1001",Comparativosimulacros!$C$4:$C$1500,"<=1005",Comparativosimulacros!$K$4:$K$1500,">0")+COUNTIFS(Comparativosimulacros!$C$4:$C$1500,">=1101",Comparativosimulacros!$C$4:$C$1500,"<=1105",Comparativosimulacros!$K$4:$K$1500,">0"))&" estudiantes)" | N3: Puntaje Global | O3: Matemática | P3: Ciencias Naturales | Q3: Sociales y Ciudadanas | R3: Lectura Crítica | S3: Inglés | T3: Verificación
A5: 601 | D5: Acevedo Castañeda Luciana | G5: 2.1 | H5: 4.38 | I5: 2.66 | J5: 3.38 | K5: 2.74 | L5: =Comparativosimulacros!M4 | N5: =ROUND(((O5*3+P5*3+Q5*3+R5*3+S5*1)/13)*5,0) | O5: 26.58 | P5: 55.97 | Q5: 33.61 | R5: 43.13 | S5: 33.54 | T5: =IF($C5="","",IF(ISNA(MATCH($C5,Comparativosimulacros!$E:$E,0)),"Falta en Comparativo","Sí está"))
A6: 601 | D6: Aguiar García Jesús Antonio | G6: 2.49 | H6: 2.77 | I6: 1.73 | J6: 3.76 | K6: 2.35 | L6: =Comparativosimulacros!M5 | N6: =ROUND(((O6*3+P6*3+Q6*3+R6*3+S6*1)/13)*5,0) | O6: 31.41 | P6: 35.42 | Q6: 21.85 | R6: 47.92 | S6: 28.75 | T6: =IF($C6="","",IF(ISNA(MATCH($C6,Comparativosimulacros!$E:$E,0)),"Falta en Comparativo","Sí está"))
A7: 601 | D7: Alcaraz Londoño Jean Pool | G7: 3.67 | H7: 3.5 | I7: 3.13 | J7: 3.38 | K7: 5 | L7: =Comparativosimulacros!M6 | N7: =ROUND(((O7*3+P7*3+Q7*3+R7*3+S7*1)/13)*5,0) | O7: 46.39 | P7: 44.72 | Q7: 39.5 | R7: 43.13 | S7: 62.29 | T7: =IF($C7="","",IF(ISNA(MATCH($C7,Comparativosimulacros!$E:$E,0)),"Falta en Comparativo","Sí está"))
A8: 601 | D8: Alcaraz Silva Cristian Kamilo | G8: 3.94 | H8: 3.5 | I8: 3.46 | J8: 1.88 | K8: 4.69 | L8: =Comparativosimulacros!M7 | N8: =ROUND(((O8*3+P8*3+Q8*3+R8*3+S8*1)/13)*5,0) | O8: 49.77 | P8: 44.72 | Q8: 43.7 | R8: 23.96 | S8: 57.5 | T8: =IF($C8="","",IF(ISNA(MATCH($C8,Comparativosimulacros!$E:$E,0)),"Falta en Comparativo","Sí está"))
A9: 601 | D9: Amaya Cadavid Mildrey Valentina | G9: 4.74 | H9: 5 | I9: 5 | J9: 4.88 | K9: 3.52 | L9: =Comparativosimulacros!M8 | N9: =ROUND(((O9*3+P9*3+Q9*3+R9*3+S9*1)/13)*5,0) | O9: 59.92 | P9: 65.83 | Q9: 63.45 | R9: 62.29 | S9: 43.13 | T9: =IF($C9="","",IF(ISNA(MATCH($C9,Comparativosimulacros!$E:$E,0)),"Falta en Comparativo","Sí está"))
A10: 601 | D10: Ballesteros Gómez María José | G10: 4.48 | H10: 2.53 | I10: 4.12 | J10: 3.38 | K10: 2.74 | L10: =Comparativosimulacros!M9 | N10: =ROUND(((O10*3+P10*3+Q10*3+R10*3+S10*1)/13)*5,0) | O10: 56.53 | P10: 32.36 | Q10: 52.1 | R10: 43.13 | S10: 33.54 | T10: =IF($C10="","",IF(ISNA(MATCH($C10,Comparativosimulacros!$E:$E,0)),"Falta en Comparativo","Sí está"))
A11: 601 | D11: Benítez Quintero Thomas | G11: 4.63 | H11: 3.35 | I11: 5 | J11: 5 | K11: 5 | L11: =Comparativosimulacros!M10 | N11: =ROUND(((O11*3+P11*3+Q11*3+R11*3+S11*1)/13)*5,0) | O11: 58.47 | P11: 42.78 | Q11: 72.27 | R11: 76.67 | S11: 76.67 | T11: =IF($C11="","",IF(ISNA(MATCH($C11,Comparativosimulacros!$E:$E,0)),"Falta en Comparativo","Sí está"))
A12: 601 | D12: Bertel Barrios Deiner Javier | G12: 3.83 | H12: 2.14 | I12: 2.39 | J12: 3.76 | K12: 3.91 | L12: =Comparativosimulacros!M11 | N12: =ROUND(((O12*3+P12*3+Q12*3+R12*3+S12*1)/13)*5,0) | O12: 48.32 | P12: 27.36 | Q12: 30.25 | R12: 47.92 | S12: 47.92 | T12: =IF($C12="","",IF(ISNA(MATCH($C12,Comparativosimulacros!$E:$E,0)),"Falta en Comparativo","Sí está"))
A13: 601 | D13: Bran David Dylan Emanuel | G13: 3.56 | H13: 3.26 | I13: 1 | J13: 3.76 | K13: 2.74 | L13: =Comparativosimulacros!M12 | N13: =ROUND(((O13*3+P13*3+Q13*3+R13*3+S13*1)/13)*5,0) | O13: 44.94 | P13: 41.67 | Q13: 11.76 | R13: 47.92 | S13: 33.54 | T13: =IF($C13="","",IF(ISNA(MATCH($C13,Comparativosimulacros!$E:$E,0)),"Falta en Comparativo","Sí está"))
A14: 601 | D14: Brand Meneses Isabella | G14: 2.64 | H14: 2.39 | I14: 1.96 | J14: 1.13 | K14: 4.69 | L14: =Comparativosimulacros!M13 | N14: =ROUND(((O14*3+P14*3+Q14*3+R14*3+S14*1)/13)*5,0) | O14: 33.34 | P14: 30.56 | Q14: 24.79 | R14: 14.38 | S14: 57.5 | T14: =IF($C14="","",IF(ISNA(MATCH($C14,Comparativosimulacros!$E:$E,0)),"Falta en Comparativo","Sí está"))
A15: 601 | D15: Carvajal Carvajal Milagros Valentina | G15: 3.33 | H15: 4.13 | I15: 4.92 | J15: 4.88 | K15: 3.52 | L15: =Comparativosimulacros!M14 | N15: =ROUND(((O15*3+P15*3+Q15*3+R15*3+S15*1)/13)*5,0) | O15: 42.04 | P15: 52.78 | Q15: 62.18 | R15: 62.29 | S15: 43.13 | T15: =IF($C15="","",IF(ISNA(MATCH($C15,Comparativosimulacros!$E:$E,0)),"Falta en Comparativo","Sí está"))
A16: 601 | D16: Carvajal Rodríguez Saray | G16: 3.44 | H16: 4.62 | I16: 5 | J16: 5 | K16: 4.69 | L16: =Comparativosimulacros!M15 | N16: =ROUND(((O16*3+P16*3+Q16*3+R16*3+S16*1)/13)*5,0) | O16: 43.49 | P16: 59.03 | Q16: 79.83 | R16: 67.08 | S16: 57.5 | T16: =IF($C16="","",IF(ISNA(MATCH($C16,Comparativosimulacros!$E:$E,0)),"Falta en Comparativo","Sí está"))
... A59: 602 | D59: Guzmán Alcaraz Tatiana | G59: 3.78 | H59: 3.47 | I59: 4.11 | J59: 3.42 | K59: 3.32 | L59: =Comparativosimulacros!M58 | N59: =ROUND(((O59*3+P59*3+Q59*3+R59*3+S59*1)/13)*5,0) | O59: 48.28 | P59: 47.92 | Q59: 56.3 | R59: 43.13 | S59: 43.13 | T59: =IF($C59="","",IF(ISNA(MATCH($C59,Comparativosimulacros!$E:$E,0)),"Falta en Comparativo","Sí está"))
A60: 602 | D60: Hernandez Gomez Jose Manuel | L60: =Comparativosimulacros!M59 | N60: =ROUND(((O60*3+P60*3+Q60*3+R60*3+S60*1)/13)*5,0) | O60: 33 | P60: 42 | Q60: 45 | R60: 63 | S60: 58 | T60: =IF($C60="","",IF(ISNA(MATCH($C60,Comparativosimulacros!$E:$E,0)),"Falta en Comparativo","Sí está"))
A61: 602 | D61: Holguin David Martina | G61: 2.79 | H61: 4.13 | I61: 2.76 | J61: 4.18 | K61: 3.69 | L61: =Comparativosimulacros!M60 | N61: =ROUND(((O61*3+P61*3+Q61*3+R61*3+S61*1)/13)*5,0) | O61: 35.65 | P61: 57.08 | Q61: 37.82 | R61: 52.71 | S61: 47.92 | T61: =IF($C61="","",IF(ISNA(MATCH($C61,Comparativosimulacros!$E:$E,0)),"Falta en Comparativo","Sí está"))
A62: 602 | D62: Holguin Granados Matias | G62: 1.34 | H62: 2.3 | I62: 2.33 | J62: 2.66 | K62: 3.69 | L62: =Comparativosimulacros!M61 | N62: =ROUND(((O62*3+P62*3+Q62*3+R62*3+S62*1)/13)*5,0) | O62: 17.12 | P62: 31.81 | Q62: 31.93 | R62: 33.54 | S62: 47.92 | T62: =IF($C62="","",IF(ISNA(MATCH($C62,Comparativosimulacros!$E:$E,0)),"Falta en Comparativo","Sí está"))
A63: 602 | D63: Holguín Bravo Iann Santiago | G63: 4.88 | H63: 5 | I63: 5 | J63: 5 | K63: 3.69 | L63: =Comparativosimulacros!M62 | N63: =ROUND(((O63*3+P63*3+Q63*3+R63*3+S63*1)/13)*5,0) | O63: 62.31 | P63: 77.08 | Q63: 79.83 | R63: 71.88 | S63: 47.92 | T63: =IF($C63="","",IF(ISNA(MATCH($C63,Comparativosimulacros!$E:$E,0)),"Falta en Comparativo","Sí está"))
A64: 602 | D64: Jurado Hurtado Juan José | G64: 4.52 | H64: 3.47 | I64: 3.19 | J64: 3.8 | K64: 3.69 | L64: =Comparativosimulacros!M63 | N64: =ROUND(((O64*3+P64*3+Q64*3+R64*3+S64*1)/13)*5,0) | O64: 57.82 | P64: 47.92 | Q64: 43.7 | R64: 47.92 | S64: 47.92 | T64: =IF($C64="","",IF(ISNA(MATCH($C64,Comparativosimulacros!$E:$E,0)),"Falta en Comparativo","Sí está"))
A65: 602 | D65: Lezcano Holguin Julian | G65: 3.78 | H65: 2.56 | I65: 3.37 | J65: 2.28 | K65: 1.11 | L65: =Comparativosimulacros!M64 | N65: =ROUND(((O65*3+P65*3+Q65*3+R65*3+S65*1)/13)*5,0) | O65: 48.28 | P65: 35.42 | Q65: 46.22 | R65: 28.75 | S65: 14.38 | T65: =IF($C65="","",IF(ISNA(MATCH($C65,Comparativosimulacros!$E:$E,0)),"Falta en Comparativo","Sí está"))
A66: 602 | D66: Lozano Villota Nicolas | G66: 3.4 | H66: 5 | I66: 4.75 | J66: 4.18 | K66: 5 | L66: =Comparativosimulacros!M65 | N66: =ROUND(((O66*3+P66*3+Q66*3+R66*3+S66*1)/13)*5,0) | O66: 43.51 | P66: 78.33 | Q66: 65.13 | R66: 52.71 | S66: 71.88 | T66: =IF($C66="","",IF(ISNA(MATCH($C66,Comparativosimulacros!$E:$E,0)),"Falta en Comparativo","Sí está"))
A67: 602 | D67: Madrid Sánchez Matías | G67: 3.54 | H67: 3.77 | I67: 4.54 | J67: 1.9 | K67: 3.69 | L67: =Comparativosimulacros!M66 | N67: =ROUND(((O67*3+P67*3+Q67*3+R67*3+S67*1)/13)*5,0) | O67: 45.19 | P67: 52.08 | Q67: 62.18 | R67: 23.96 | S67: 47.92 | T67: =IF($C67="","",IF(ISNA(MATCH($C67,Comparativosimulacros!$E:$E,0)),"Falta en Comparativo","Sí está"))
A68: 602 | D68: Moreno García Anthony | G68: 2.55 | H68: 2.89 | I68: 1.81 | J68: 3.04 | K68: 5 | L68: =Comparativosimulacros!M67 | N68: =ROUND(((O68*3+P68*3+Q68*3+R68*3+S68*1)/13)*5,0) | O68: 32.56 | P68: 39.86 | Q68: 24.79 | R68: 38.33 | S68: 71.88 | T68: =IF($C68="","",IF(ISNA(MATCH($C68,Comparativosimulacros!$E:$E,0)),"Falta en Comparativo","Sí está"))
A69: 602 | D69: Ortiz Moreno Gerónimo | G69: 1.93 | H69: 5 | I69: 3.28 | J69: 3.04 | K69: 5 | L69: =Comparativosimulacros!M68 | N69: =ROUND(((O69*3+P69*3+Q69*3+R69*3+S69*1)/13)*5,0) | O69: 24.71 | P69: 83.33 | Q69: 44.96 | R69: 38.33 | S69: 67.08 | T69: =IF($C69="","",IF(ISNA(MATCH($C69,Comparativosimulacros!$E:$E,0)),"Falta en Comparativo","Sí está"))
A70: 602 | D70: Panesso Jimenez Andres | G70: 4.52 | H70: 4.18 | I70: 4.44 | J70: 1.52 | K70: 4.06 | L70: =Comparativosimulacros!M69 | N70: =ROUND(((O70*3+P70*3+Q70*3+R70*3+S70*1)/13)*5,0) | O70: 57.82 | P70: 57.78 | Q70: 60.92 | R70: 19.17 | S70: 52.71 | T70: =IF($C70="","",IF(ISNA(MATCH($C70,Comparativosimulacros!$E:$E,0)),"Falta en Comparativo","Sí está"))
A71: 602 | D71: Perez Gonzalez Gabriel | G71: 3.18 | H71: 2.34 | I71: 3.49 | J71: 3.42 | K71: 3.32 | L71: =Comparativosimulacros!M70 | N71: =ROUND(((O71*3+P71*3+Q71*3+R71*3+S71*1)/13)*5,0) | O71: 40.69 | P71: 32.36 | Q71: 47.9 | R71: 43.13 | S71: 43.13 | T71: =IF($C71="","",IF(ISNA(MATCH($C71,Comparativosimulacros!$E:$E,0)),"Falta en Comparativo","Sí está"))
A72: 602 | D72: Perez Gutierrez Cristian | L72: =Comparativosimulacros!M71 | N72: =ROUND(((O72*3+P72*3+Q72*3+R72*3+S72*1)/13)*5,0) | O72: 45 | P72: 43 | Q72: 74 | R72: 54 | S72: 46 | T72: =IF($C72="","",IF(ISNA(MATCH($C72,Comparativosimulacros!$E:$E,0)),"Falta en Comparativo","Sí está"))
A73: 602 | D73: Pérez Valencia Miguel Ángel | G73: 5 | H73: 4.27 | I73: 4.44 | J73: 4.95 | K73: 5 | L73: =Comparativosimulacros!M72 | N73: =ROUND(((O73*3+P73*3+Q73*3+R73*3+S73*1)/13)*5,0) | O73: 67.08 | P73: 59.03 | Q73: 60.92 | R73: 62.29 | S73: 71.88 | T73: =IF($C73="","",IF(ISNA(MATCH($C73,Comparativosimulacros!$E:$E,0)),"Falta en Comparativo","Sí está"))
A74: 602 | D74: Salas Arcila Salome | G74: 2.57 | H74: 2.42 | I74: 4.23 | J74: 2.66 | K74: 2.21 | L74: =Comparativosimulacros!M73 | N74: =ROUND(((O74*3+P74*3+Q74*3+R74*3+S74*1)/13)*5,0) | O74: 32.84 | P74: 33.47 | Q74: 57.98 | R74: 33.54 | S74: 28.75 | T74: =IF($C74="","",IF(ISNA(MATCH($C74,Comparativosimulacros!$E:$E,0)),"Falta en Comparativo","Sí está"))
A75: 602 | D75: Valencia Holguín Mariángel | G75: 3.29 | H75: 2.64 | I75: 2.42 | J75: 2.28 | K75: 2.58 | L75: =Comparativosimulacros!M74 | N75: =ROUND(((O75*3+P75*3+Q75*3+R75*3+S75*1)/13)*5,0) | O75: 42.1 | P75: 36.53 | Q75: 33.19 | R75: 28.75 | S75: 33.54 | T75: =IF($C75="","",IF(ISNA(MATCH($C75,Comparativosimulacros!$E:$E,0)),"Falta en Comparativo","Sí está"))
A76: 602 | D76: Vidales Silva Johan Stiven | G76: 3.29 | H76: 2.43 | I76: 1.47 | J76: 3.42 | K76: 4.43 | L76: =Comparativosimulacros!M75 | N76: =ROUND(((O76*3+P76*3+Q76*3+R76*3+S76*1)/13)*5,0) | O76: 42.1 | P76: 33.61 | Q76: 20.17 | R76: 43.13 | S76: 57.5 | T76: =IF($C76="","",IF(ISNA(MATCH($C76,Comparativosimulacros!$E:$E,0)),"Falta en Comparativo","Sí está"))
A77: 602 | D77: Villa Goez Maria Salome | G77: 3.29 | H77: 2.7 | I77: 4.44 | J77: 3.8 | K77: 1.48 | L77: =Comparativosimulacros!M76 | N77: =ROUND(((O77*3+P77*3+Q77*3+R77*3+S77*1)/13)*5,0) | O77: 42.1 | P77: 37.36 | Q77: 60.92 | R77: 47.92 | S77: 19.17 | T77: =IF($C77="","",IF(ISNA(MATCH($C77,Comparativosimulacros!$E:$E,0)),"Falta en Comparativo","Sí está"))
A78: 602 | D78: Villa Molina José Manuel | G78: 2.44 | H78: 2.34 | I78: 1.99 | J78: 3.8 | K78: 2.58 | L78: =Comparativosimulacros!M77 | N78: =ROUND(((O78*3+P78*3+Q78*3+R78*3+S78*1)/13)*5,0) | O78: 31.16 | P78: 32.36 | Q78: 27.31 | R78: 47.92 | S78: 33.54 | T78: =IF($C78="","",IF(ISNA(MATCH($C78,Comparativosimulacros!$E:$E,0)),"Falta en Comparativo","Sí está"))
A79: 602 | D79: Villegas Chaverra Eilyn Marín | G79: 4.74 | H79: 2.93 | I79: 5 | J79: 3.8 | K79: 2.58 | L79: =Comparativosimulacros!M78 | N79: =ROUND(((O79*3+P79*3+Q79*3+R79*3+S79*1)/13)*5,0) | O79: 60.63 | P79: 40.42 | Q79: 76.89 | R79: 47.92 | S79: 33.54 | T79: =IF($C79="","",IF(ISNA(MATCH($C79,Comparativosimulacros!$E:$E,0)),"Falta en Comparativo","Sí está"))
A80: 603 | D80: Aguinaga Ruiz Valentina | G80: 4.9 | H80: 5 | I80: 4.6 | J80: 5 | K80: 4.85 | L80: =Comparativosimulacros!M79 | N80: =ROUND(((O80*3+P80*3+Q80*3+R80*3+S80*1)/13)*5,0) | O80: 61.97 | P80: 67.08 | Q80: 59.24 | R80: 67.08 | S80: 59.58 | T80: =IF($C80="","",IF(ISNA(MATCH($C80,Comparativosimulacros!$E:$E,0)),"Falta en Comparativo","Sí está"))
A81: 603 | D81: Amasará Ramírez Matías | G81: 4.53 | H81: 2.8 | I81: 4.04 | J81: 3.32 | K81: 3.52 | L81: =Comparativosimulacros!M80 | N81: =ROUND(((O81*3+P81*3+Q81*3+R81*3+S81*1)/13)*5,0) | O81: 57.25 | P81: 36.04 | Q81: 52.1 | R81: 43.13 | S81: 43.33 | T81: =IF($C81="","",IF(ISNA(MATCH($C81,Comparativosimulacros!$E:$E,0)),"Falta en Comparativo","Sí está"))
A82: 603 | D82: Bermudez Bran Jonas | G82: 2.58 | H82: 1.18 | I82: 2.15 | J82: 4.05 | K82: 3.97 | L82: =Comparativosimulacros!M81 | N82: =ROUND(((O82*3+P82*3+Q82*3+R82*3+S82*1)/13)*5,0) | O82: 32.61 | P82: 15.21 | Q82: 27.73 | R82: 52.71 | S82: 48.75 | T82: =IF($C82="","",IF(ISNA(MATCH($C82,Comparativosimulacros!$E:$E,0)),"Falta en Comparativo","Sí está"))
A83: 603 | D83: Bran Quiroz Paulina | G83: 4.9 | H83: 3.83 | I83: 4.86 | J83: 4.42 | K83: 4.41 | L83: =Comparativosimulacros!M82 | N83: =ROUND(((O83*3+P83*3+Q83*3+R83*3+S83*1)/13)*5,0) | O83: 61.97 | P83: 49.17 | Q83: 62.61 | R83: 57.5 | S83: 54.17 | T83: =IF($C83="","",IF(ISNA(MATCH($C83,Comparativosimulacros!$E:$E,0)),"Falta en Comparativo","Sí está"))
A84: 603 | D84: Carrasquilla Diaz Emanuel | G84: 1.56 | H84: 3.24 | I84: 2.58 | J84: 3.32 | K84: 3.97 | L84: =Comparativosimulacros!M83 | N84: =ROUND(((O84*3+P84*3+Q84*3+R84*3+S84*1)/13)*5,0) | O84: 19.66 | P84: 41.67 | Q84: 33.19 | R84: 43.13 | S84: 48.75 | T84: =IF($C84="","",IF(ISNA(MATCH($C84,Comparativosimulacros!$E:$E,0)),"Falta en Comparativo","Sí está"))
...

Sheet SegundoSimulacro
E2: Resultados Segundo Simulacro | O2: Puntaje por área (0–100)
A3: Grupo | B3: Sexo | C3: Documento | D3: ESTUDIANTES | E3: Enlace Imagen | F3: PDF | G3: Matemática | H3: Ciencias Naturales | I3: Sociales y Ciudadanas | J3: Lectura Crítica | K3: Inglés | L3: Posición dentro del grupo | M3: Posición dentro de décimo | N3: Puntaje Global | O3: Matemática | P3: Ciencias Naturales | Q3: Sociales y Ciudadanas | R3: Lectura Crítica | S3: Inglés | T3: Verificación
A5: 601 | D5: Acevedo Castañeda Luciana | G5: 2.77 | H5: 3.06 | I5: 3.77 | J5: 3.35 | K5: 4.42 | L5: =IF(OR($A5="",$N5=0),"",COUNTIFS($A$5:$A$1500,$A5,$N$5:$N$1500,">"&$N5)+1) | M5: =IF(OR($A5="",$N5=0),"",IF(AND($A5>=1001,$A5<=1005),COUNTIFS($A$5:$A$1500,">=1001",$A$5:$A$1500,"<=1005",$N$5:$N$1500,">"&$N5)+1,"")) | N5: =ROUND(((O5*3+P5*3+Q5*3+R5*3+S5*1)/13)*5,0) | O5: 44 | P5: 47.26 | Q5: 52.25 | R5: 52.5 | S5: 64.17 | T5: =IF($C5="","",IF(ISNA(MATCH($C5,Comparativosimulacros!$E:$E,0)),"Falta en Comparativo","Sí está"))
A6: 601 | D6: Aguiar García Jesús Antonio | G6: 2.77 | H6: 3.06 | I6: 2.58 | J6: 2.24 | K6: 4.11 | L6: =IF(OR($A6="",$N6=0),"",COUNTIFS($A$5:$A$1500,$A6,$N$5:$N$1500,">"&$N6)+1) | M6: =IF(OR($A6="",$N6=0),"",IF(AND($A6>=1001,$A6<=1005),COUNTIFS($A$5:$A$1500,">=1001",$A$5:$A$1500,"<=1005",$N$5:$N$1500,">"&$N6)+1,"")) | N6: =ROUND(((O6*3+P6*3+Q6*3+R6*3+S6*1)/13)*5,0) | O6: 44 | P6: 47.26 | Q6: 35.75 | R6: 35 | S6: 59.58 | T6: =IF($C6="","",IF(ISNA(MATCH($C6,Comparativosimulacros!$E:$E,0)),"Falta en Comparativo","Sí está"))
A7: 601 | D7: Alcaraz Londoño Jean Pool | G7: 3.29 | H7: 3.95 | I7: 2.58 | J7: 2.51 | K7: 4.74 | L7: =IF(OR($A7="",$N7=0),"",COUNTIFS($A$5:$A$1500,$A7,$N$5:$N$1500,">"&$N7)+1) | M7: =IF(OR($A7="",$N7=0),"",IF(AND($A7>=1001,$A7<=1005),COUNTIFS($A$5:$A$1500,">=1001",$A$5:$A$1500,"<=1005",$N$5:$N$1500,">"&$N7)+1,"")) | N7: =ROUND(((O7*3+P7*3+Q7*3+R7*3+S7*1)/13)*5,0) | O7: 52.25 | P7: 60.95 | Q7: 35.75 | R7: 39.38 | S7: 68.75 | T7: =IF($C7="","",IF(ISNA(MATCH($C7,Comparativosimulacros!$E:$E,0)),"Falta en Comparativo","Sí está"))
A8: 601 | D8: Alcaraz Silva Cristian Kamilo | G8: 3.46 | H8: 3.24 | I8: 2.97 | J8: 2.79 | K8: 2.84 | L8: =IF(OR($A8="",$N8=0),"",COUNTIFS($A$5:$A$1500,$A8,$N$5:$N$1500,">"&$N8)+1) | M8: =IF(OR($A8="",$N8=0),"",IF(AND($A8>=1001,$A8<=1005),COUNTIFS($A$5:$A$1500,">=1001",$A$5:$A$1500,"<=1005",$N$5:$N$1500,">"&$N8)+1,"")) | N8: =ROUND(((O8*3+P8*3+Q8*3+R8*3+S8*1)/13)*5,0) | O8: 55 | P8: 49.94 | Q8: 41.25 | R8: 43.75 | S8: 41.25 | T8: =IF($C8="","",IF(ISNA(MATCH($C8,Comparativosimulacros!$E:$E,0)),"Falta en Comparativo","Sí está"))
A9: 601 | D9: Ballesteros Gómez María José | G9: 3.98 | H9: 3.25 | I9: 4.56 | J9: 3.63 | K9: 3.48 | L9: =IF(OR($A9="",$N9=0),"",COUNTIFS($A$5:$A$1500,$A9,$N$5:$N$1500,">"&$N9)+1) | M9: =IF(OR($A9="",$N9=0),"",IF(AND($A9>=1001,$A9<=1005),COUNTIFS($A$5:$A$1500,">=1001",$A$5:$A$1500,"<=1005",$N$5:$N$1500,">"&$N9)+1,"")) | N9: =ROUND(((O9*3+P9*3+Q9*3+R9*3+S9*1)/13)*5,0) | O9: 63.25 | P9: 50.18 | Q9: 63.25 | R9: 56.88 | S9: 50.42 | T9: =IF($C9="","",IF(ISNA(MATCH($C9,Comparativosimulacros!$E:$E,0)),"Falta en Comparativo","Sí está"))
A10: 601 | D10: Benítez Quintero Thomas | G10: 5 | H10: 3.85 | I10: 5 | J10: 4.47 | K10: 5 | L10: =IF(OR($A10="",$N10=0),"",COUNTIFS($A$5:$A$1500,$A10,$N$5:$N$1500,">"&$N10)+1) | M10: =IF(OR($A10="",$N10=0),"",IF(AND($A10>=1001,$A10<=1005),COUNTIFS($A$5:$A$1500,">=1001",$A$5:$A$1500,"<=1005",$N$5:$N$1500,">"&$N10)+1,"")) | N10: =ROUND(((O10*3+P10*3+Q10*3+R10*3+S10*1)/13)*5,0) | O10: 79.75 | P10: 59.35 | Q10: 77 | R10: 70 | S10: 91.67 | T10: =IF($C10="","",IF(ISNA(MATCH($C10,Comparativosimulacros!$E:$E,0)),"Falta en Comparativo","Sí está"))
A11: 601 | D11: Bertel Barrios Deiner Javier | G11: 5 | H11: 1.79 | I11: 1.78 | J11: 3.91 | K11: 1.9 | L11: =IF(OR($A11="",$N11=0),"",COUNTIFS($A$5:$A$1500,$A11,$N$5:$N$1500,">"&$N11)+1) | M11: =IF(OR($A11="",$N11=0),"",IF(AND($A11>=1001,$A11<=1005),COUNTIFS($A$5:$A$1500,">=1001",$A$5:$A$1500,"<=1005",$N$5:$N$1500,">"&$N11)+1,"")) | N11: =ROUND(((O11*3+P11*3+Q11*3+R11*3+S11*1)/13)*5,0) | O11: 83 | P11: 27.62 | Q11: 24.75 | R11: 61.25 | S11: 27.5 | T11: =IF($C11="","",IF(ISNA(MATCH($C11,Comparativosimulacros!$E:$E,0)),"Falta en Comparativo","Sí está"))
A12: 601 | D12: Bran David Dylan Emanuel | G12: 5 | H12: 3.05 | I12: 3.96 | J12: 4.19 | K12: 4.74 | L12: =IF(OR($A12="",$N12=0),"",COUNTIFS($A$5:$A$1500,$A12,$N$5:$N$1500,">"&$N12)+1) | M12: =IF(OR($A12="",$N12=0),"",IF(AND($A12>=1001,$A12<=1005),COUNTIFS($A$5:$A$1500,">=1001",$A$5:$A$1500,"<=1005",$N$5:$N$1500,">"&$N12)+1,"")) | N12: =ROUND(((O12*3+P12*3+Q12*3+R12*3+S12*1)/13)*5,0) | O12: 85.25 | P12: 47.02 | Q12: 55 | R12: 65.63 | S12: 68.75 | T12: =IF($C12="","",IF(ISNA(MATCH($C12,Comparativosimulacros!$E:$E,0)),"Falta en Comparativo","Sí está"))
A13: 601 | D13: Brand Meneses Isabella | G13: 1.9 | H13: 3.84 | I13: 2.18 | J13: 2.24 | K13: 2.21 | L13: =IF(OR($A13="",$N13=0),"",COUNTIFS($A$5:$A$1500,$A13,$N$5:$N$1500,">"&$N13)+1) | M13: =IF(OR($A13="",$N13=0),"",IF(AND($A13>=1001,$A13<=1005),COUNTIFS($A$5:$A$1500,">=1001",$A$5:$A$1500,"<=1005",$N$5:$N$1500,">"&$N13)+1,"")) | N13: =ROUND(((O13*3+P13*3+Q13*3+R13*3+S13*1)/13)*5,0) | O13: 30.25 | P13: 59.17 | Q13: 30.25 | R13: 35 | S13: 32.08 | T13: =IF($C13="","",IF(ISNA(MATCH($C13,Comparativosimulacros!$E:$E,0)),"Falta en Comparativo","Sí está"))
A14: 601 | D14: Amaya Cadavid Mildrey Valentina | G14: 2.6 | H14: 5 | I14: 3.77 | J14: 4.47 | K14: 5 | L14: =IF(OR($A14="",$N14=0),"",COUNTIFS($A$5:$A$1500,$A14,$N$5:$N$1500,">"&$N14)+1) | M14: =IF(OR($A14="",$N14=0),"",IF(AND($A14>=1001,$A14<=1005),COUNTIFS($A$5:$A$1500,">=1001",$A$5:$A$1500,"<=1005",$N$5:$N$1500,">"&$N14)+1,"")) | N14: =ROUND(((O14*3+P14*3+Q14*3+R14*3+S14*1)/13)*5,0) | O14: 41.25 | P14: 80.95 | Q14: 52.25 | R14: 70 | S14: 77.92 | T14: =IF($C14="","",IF(ISNA(MATCH($C14,Comparativosimulacros!$E:$E,0)),"Falta en Comparativo","Sí está"))
A15: 601 | D15: Carvajal Carvajal Milagros Valentina | G15: 3.46 | H15: 3.31 | I15: 2.97 | J15: 4.19 | K15: 3.48 | L15: =IF(OR($A15="",$N15=0),"",COUNTIFS($A$5:$A$1500,$A15,$N$5:$N$1500,">"&$N15)+1) | M15: =IF(OR($A15="",$N15=0),"",IF(AND($A15>=1001,$A15<=1005),COUNTIFS($A$5:$A$1500,">=1001",$A$5:$A$1500,"<=1005",$N$5:$N$1500,">"&$N15)+1,"")) | N15: =ROUND(((O15*3+P15*3+Q15*3+R15*3+S15*1)/13)*5,0) | O15: 55 | P15: 51.07 | Q15: 41.25 | R15: 65.63 | S15: 50.42 | T15: =IF($C15="","",IF(ISNA(MATCH($C15,Comparativosimulacros!$E:$E,0)),"Falta en Comparativo","Sí está"))
A16: 601 | D16: Díaz Ara Moisés | G16: 4.33 | H16: 5 | I16: 5 | J16: 4.75 | K16: 4.74 | L16: =IF(OR($A16="",$N16=0),"",COUNTIFS($A$5:$A$1500,$A16,$N$5:$N$1500,">"&$N16)+1) | M16: =IF(OR($A16="",$N16=0),"",IF(AND($A16>=1001,$A16<=1005),COUNTIFS($A$5:$A$1500,">=1001",$A$5:$A$1500,"<=1005",$N$5:$N$1500,">"&$N16)+1,"")) | N16: =ROUND(((O16*3+P16*3+Q16*3+R16*3+S16*1)/13)*5,0) | O16: 68.75 | P16: 80.95 | Q16: 79.75 | R16: 74.38 | S16: 68.75 | T16: =IF($C16="","",IF(ISNA(MATCH($C16,Comparativosimulacros!$E:$E,0)),"Falta en Comparativo","Sí está"))
... A69: 602 | D69: Moreno García Anthony | G69: 2.84 | H69: 1.34 | I69: 2.71 | J69: 2.88 | K69: 2.07 | L69: =IF(OR($A69="",$N69=0),"",COUNTIFS($A$5:$A$1500,$A69,$N$5:$N$1500,">"&$N69)+1) | M69: =IF(OR($A69="",$N69=0),"",IF(AND($A69>=1001,$A69<=1005),COUNTIFS($A$5:$A$1500,">=1001",$A$5:$A$1500,"<=1005",$N$5:$N$1500,">"&$N69)+1,"")) | N69: =ROUND(((O69*3+P69*3+Q69*3+R69*3+S69*1)/13)*5,0) | O69: 42.5 | P69: 21.73 | Q69: 38.5 | R69: 43.75 | S69: 32.08 | T69: =IF($C69="","",IF(ISNA(MATCH($C69,Comparativosimulacros!$E:$E,0)),"Falta en Comparativo","Sí está"))
A70: 602 | D70: Ortiz Moreno Gerónimo | L70: =IF(OR($A70="",$N70=0),"",COUNTIFS($A$5:$A$1500,$A70,$N$5:$N$1500,">"&$N70)+1) | M70: =IF(OR($A70="",$N70=0),"",IF(AND($A70>=1001,$A70<=1005),COUNTIFS($A$5:$A$1500,">=1001",$A$5:$A$1500,"<=1005",$N$5:$N$1500,">"&$N70)+1,"")) | N70: =ROUND(((O70*3+P70*3+Q70*3+R70*3+S70*1)/13)*5,0) | O70: 52 | P70: 36 | Q70: 30 | R70: 30 | S70: 35 | T70: =IF($C70="","",IF(ISNA(MATCH($C70,Comparativosimulacros!$E:$E,0)),"Falta en Comparativo","Sí está"))
A71: 602 | D71: Panesso Jimenez Andres | G71: 3.02 | H71: 4.59 | I71: 4.06 | J71: 3.74 | K71: 3.84 | L71: =IF(OR($A71="",$N71=0),"",COUNTIFS($A$5:$A$1500,$A71,$N$5:$N$1500,">"&$N71)+1) | M71: =IF(OR($A71="",$N71=0),"",IF(AND($A71>=1001,$A71<=1005),COUNTIFS($A$5:$A$1500,">=1001",$A$5:$A$1500,"<=1005",$N$5:$N$1500,">"&$N71)+1,"")) | N71: =ROUND(((O71*3+P71*3+Q71*3+R71*3+S71*1)/13)*5,0) | O71: 45.25 | P71: 74.4 | Q71: 57.75 | R71: 56.88 | S71: 59.58 | T71: =IF($C71="","",IF(ISNA(MATCH($C71,Comparativosimulacros!$E:$E,0)),"Falta en Comparativo","Sí está"))
A72: 602 | D72: Perez Gutierrez Cristian | G72: 5 | H72: 2.81 | I72: 5 | J72: 3.16 | K72: 1.77 | L72: =IF(OR($A72="",$N72=0),"",COUNTIFS($A$5:$A$1500,$A72,$N$5:$N$1500,">"&$N72)+1) | M72: =IF(OR($A72="",$N72=0),"",IF(AND($A72>=1001,$A72<=1005),COUNTIFS($A$5:$A$1500,">=1001",$A$5:$A$1500,"<=1005",$N$5:$N$1500,">"&$N72)+1,"")) | N72: =ROUND(((O72*3+P72*3+Q72*3+R72*3+S72*1)/13)*5,0) | O72: 75.25 | P72: 45.54 | Q72: 74.25 | R72: 48.13 | S72: 27.5 | T72: =IF($C72="","",IF(ISNA(MATCH($C72,Comparativosimulacros!$E:$E,0)),"Falta en Comparativo","Sí está"))
A73: 602 | D73: Pérez Valencia Miguel Ángel | G73: 3.39 | H73: 4.33 | I73: 4.06 | J73: 4.31 | K73: 3.84 | L73: =IF(OR($A73="",$N73=0),"",COUNTIFS($A$5:$A$1500,$A73,$N$5:$N$1500,">"&$N73)+1) | M73: =IF(OR($A73="",$N73=0),"",IF(AND($A73>=1001,$A73<=1005),COUNTIFS($A$5:$A$1500,">=1001",$A$5:$A$1500,"<=1005",$N$5:$N$1500,">"&$N73)+1,"")) | N73: =ROUND(((O73*3+P73*3+Q73*3+R73*3+S73*1)/13)*5,0) | O73: 50.75 | P73: 70.24 | Q73: 57.75 | R73: 65.63 | S73: 59.58 | T73: =IF($C73="","",IF(ISNA(MATCH($C73,Comparativosimulacros!$E:$E,0)),"Falta en Comparativo","Sí está"))
A74: 602 | D74: Salas Arcila Salome | G74: 3.47 | H74: 3.12 | I74: 3.48 | J74: 3.16 | K74: 3.25 | L74: =IF(OR($A74="",$N74=0),"",COUNTIFS($A$5:$A$1500,$A74,$N$5:$N$1500,">"&$N74)+1) | M74: =IF(OR($A74="",$N74=0),"",IF(AND($A74>=1001,$A74<=1005),COUNTIFS($A$5:$A$1500,">=1001",$A$5:$A$1500,"<=1005",$N$5:$N$1500,">"&$N74)+1,"")) | N74: =ROUND(((O74*3+P74*3+Q74*3+R74*3+S74*1)/13)*5,0) | O74: 52 | P74: 50.6 | Q74: 49.5 | R74: 48.13 | S74: 50.42 | T74: =IF($C74="","",IF(ISNA(MATCH($C74,Comparativosimulacros!$E:$E,0)),"Falta en Comparativo","Sí está"))
A75: 602 | D75: Valencia Holguín Mariángel | G75: 1.37 | H75: 1.91 | I75: 2.71 | J75: 2.01 | K75: 2.07 | L75: =IF(OR($A75="",$N75=0),"",COUNTIFS($A$5:$A$1500,$A75,$N$5:$N$1500,">"&$N75)+1) | M75: =IF(OR($A75="",$N75=0),"",IF(AND($A75>=1001,$A75<=1005),COUNTIFS($A$5:$A$1500,">=1001",$A$5:$A$1500,"<=1005",$N$5:$N$1500,">"&$N75)+1,"")) | N75: =ROUND(((O75*3+P75*3+Q75*3+R75*3+S75*1)/13)*5,0) | O75: 20.5 | P75: 30.95 | Q75: 38.5 | R75: 30.63 | S75: 32.08 | T75: =IF($C75="","",IF(ISNA(MATCH($C75,Comparativosimulacros!$E:$E,0)),"Falta en Comparativo","Sí está"))
A76: 602 | D76: Vidales Silva Johan Stiven | G76: 4.02 | H76: 1.74 | I76: 3.1 | J76: 1.44 | K76: 3.84 | L76: =IF(OR($A76="",$N76=0),"",COUNTIFS($A$5:$A$1500,$A76,$N$5:$N$1500,">"&$N76)+1) | M76: =IF(OR($A76="",$N76=0),"",IF(AND($A76>=1001,$A76<=1005),COUNTIFS($A$5:$A$1500,">=1001",$A$5:$A$1500,"<=1005",$N$5:$N$1500,">"&$N76)+1,"")) | N76: =ROUND(((O76*3+P76*3+Q76*3+R76*3+S76*1)/13)*5,0) | O76: 60.25 | P76: 28.27 | Q76: 44 | R76: 21.88 | S76: 59.58 | T76: =IF($C76="","",IF(ISNA(MATCH($C76,Comparativosimulacros!$E:$E,0)),"Falta en Comparativo","Sí está"))
A77: 602 | D77: Villa Molina José Manuel | G77: 2.66 | H77: 2.74 | I77: 2.13 | J77: 2.88 | K77: 2.36 | L77: =IF(OR($A77="",$N77=0),"",COUNTIFS($A$5:$A$1500,$A77,$N$5:$N$1500,">"&$N77)+1) | M77: =IF(OR($A77="",$N77=0),"",IF(AND($A77>=1001,$A77<=1005),COUNTIFS($A$5:$A$1500,">=1001",$A$5:$A$1500,"<=1005",$N$5:$N$1500,">"&$N77)+1,"")) | N77: =ROUND(((O77*3+P77*3+Q77*3+R77*3+S77*1)/13)*5,0) | O77: 39.75 | P77: 44.35 | Q77: 30.25 | R77: 43.75 | S77: 36.67 | T77: =IF($C77="","",IF(ISNA(MATCH($C77,Comparativosimulacros!$E:$E,0)),"Falta en Comparativo","Sí está"))
A78: 602 | D78: Villegas Chaverra Eilyn Marín | G78: 3.39 | H78: 3.95 | I78: 3.1 | J78: 3.45 | K78: 3.54 | L78: =IF(OR($A78="",$N78=0),"",COUNTIFS($A$5:$A$1500,$A78,$N$5:$N$1500,">"&$N78)+1) | M78: =IF(OR($A78="",$N78=0),"",IF(AND($A78>=1001,$A78<=1005),COUNTIFS($A$5:$A$1500,">=1001",$A$5:$A$1500,"<=1005",$N$5:$N$1500,">"&$N78)+1,"")) | N78: =ROUND(((O78*3+P78*3+Q78*3+R78*3+S78*1)/13)*5,0) | O78: 50.75 | P78: 63.99 | Q78: 44 | R78: 52.5 | S78: 55 | T78: =IF($C78="","",IF(ISNA(MATCH($C78,Comparativosimulacros!$E:$E,0)),"Falta en Comparativo","Sí está"))
A79: 603 | D79: Aguinaga Ruiz Valentina | G79: 3.21 | H79: 5 | I79: 4.73 | J79: 3.82 | K79: 3.9 | L79: =IF(OR($A79="",$N79=0),"",COUNTIFS($A$5:$A$1500,$A79,$N$5:$N$1500,">"&$N79)+1) | M79: =IF(OR($A79="",$N79=0),"",IF(AND($A79>=1001,$A79<=1005),COUNTIFS($A$5:$A$1500,">=1001",$A$5:$A$1500,"<=1005",$N$5:$N$1500,">"&$N79)+1,"")) | N79: =ROUND(((O79*3+P79*3+Q79*3+R79*3+S79*1)/13)*5,0) | O79: 46.75 | P79: 75.89 | Q79: 65.25 | R79: 56.88 | S79: 57.5 | T79: =IF($C79="","",IF(ISNA(MATCH($C79,Comparativosimulacros!$E:$E,0)),"Falta en Comparativo","Sí está"))
A80: 603 | D80: Amasará Ramírez Matías | G80: 5 | H80: 4.61 | I80: 5 | J80: 4.11 | K80: 5 | L80: =IF(OR($A80="",$N80=0),"",COUNTIFS($A$5:$A$1500,$A80,$N$5:$N$1500,">"&$N80)+1) | M80: =IF(OR($A80="",$N80=0),"",IF(AND($A80>=1001,$A80<=1005),COUNTIFS($A$5:$A$1500,">=1001",$A$5:$A$1500,"<=1005",$N$5:$N$1500,">"&$N80)+1,"")) | N80: =ROUND(((O80*3+P80*3+Q80*3+R80*3+S80*1)/13)*5,0) | O80: 88 | P80: 66.67 | Q80: 69.38 | R80: 61.25 | S80: 81.46 | T80: =IF($C80="","",IF(ISNA(MATCH($C80,Comparativosimulacros!$E:$E,0)),"Falta en Comparativo","Sí está"))
A81: 603 | D81: Bermudez Bran Jonas | G81: 3.4 | H81: 2.78 | I81: 2.04 | J81: 3.53 | K81: 2.27 | L81: =IF(OR($A81="",$N81=0),"",COUNTIFS($A$5:$A$1500,$A81,$N$5:$N$1500,">"&$N81)+1) | M81: =IF(OR($A81="",$N81=0),"",IF(AND($A81>=1001,$A81<=1005),COUNTIFS($A$5:$A$1500,">=1001",$A$5:$A$1500,"<=1005",$N$5:$N$1500,">"&$N81)+1,"")) | N81: =ROUND(((O81*3+P81*3+Q81*3+R81*3+S81*1)/13)*5,0) | O81: 49.5 | P81: 40.18 | Q81: 28.13 | R81: 52.5 | S81: 33.54 | T81: =IF($C81="","",IF(ISNA(MATCH($C81,Comparativosimulacros!$E:$E,0)),"Falta en Comparativo","Sí está"))
A82: 603 | D82: Bran Quiroz Paulina | G82: 5 | H82: 4.2 | I82: 5 | J82: 4.7 | K82: 5 | L82: =IF(OR($A82="",$N82=0),"",COUNTIFS($A$5:$A$1500,$A82,$N$5:$N$1500,">"&$N82)+1) | M82: =IF(OR($A82="",$N82=0),"",IF(AND($A82>=1001,$A82<=1005),COUNTIFS($A$5:$A$1500,">=1001",$A$5:$A$1500,"<=1005",$N$5:$N$1500,">"&$N82)+1,"")) | N82: =ROUND(((O82*3+P82*3+Q82*3+R82*3+S82*1)/13)*5,0) | O82: 74.25 | P82: 60.71 | Q82: 72.38 | R82: 70 | S82: 76.67 | T82: =IF($C82="","",IF(ISNA(MATCH($C82,Comparativosimulacros!$E:$E,0)),"Falta en Comparativo","Sí está"))
A83: 603 | D83: Cañola Fernández Salomé | L83: =IF(OR($A83="",$N83=0),"",COUNTIFS($A$5:$A$1500,$A83,$N$5:$N$1500,">"&$N83)+1) | M83: =IF(OR($A83="",$N83=0),"",IF(AND($A83>=1001,$A83<=1005),COUNTIFS($A$5:$A$1500,">=1001",$A$5:$A$1500,"<=1005",$N$5:$N$1500,">"&$N83)+1,"")) | N83: =ROUND(((O83*3+P83*3+Q83*3+R83*3+S83*1)/13)*5,0) | O83: 48 | P83: 76 | Q83: 72 | R83: 70 | S83: 79 | T83: =IF($C83="","",IF(ISNA(MATCH($C83,Comparativosimulacros!$E:$E,0)),"Falta en Comparativo","Sí está"))
A84: 603 | D84: Correa Quiroz Anaisabel | G84: 4.92 | H84: 4.67 | I84: 5 | J84: 5 | K84: 4.55 | L84: =IF(OR($A84="",$N84=0),"",COUNTIFS($A$5:$A$1500,$A84,$N$5:$N$1500,">"&$N84)+1) | M84: =IF(OR($A84="",$N84=0),"",IF(AND($A84>=1001,$A84<=1005),COUNTIFS($A$5:$A$1500,">=1001",$A$5:$A$1500,"<=1005",$N$5:$N$1500,">"&$N84)+1,"")) | N84: =ROUND(((O84*3+P84*3+Q84*3+R84*3+S84*1)/13)*5,0) | O84: 71.5 | P84: 67.56 | Q84: 78.38 | R84: 78.75 | S84: 67.08 | T84: =IF($C84="","",IF(ISNA(MATCH($C84,Comparativosimulacros!$E:$E,0)),"Falta en Comparativo","Sí está"))
A85: 603 | D85: De Vrijer Escudero Manolo | G85: 1.89 | H85: 2.96 | I85: 5 | J85: 4.41 | K85: 4.22 | L85: =IF(OR($A85="",$N85=0),"",COUNTIFS($A$5:$A$1500,$A85,$N$5:$N$1500,">"&$N85)+1) | M85: =IF(OR($A85="",$N85=0),"",IF(AND($A85>=1001,$A85<=1005),COUNTIFS($A$5:$A$1500,">=1001",$A$5:$A$1500,"<=1005",$N$5:$N$1500,">"&$N85)+1,"")) | N85: =ROUND(((O85*3+P85*3+Q85*3+R85*3+S85*1)/13)*5,0) | O85: 27.5 | P85: 42.86 | Q85: 75.38 | R85: 65.63 | S85: 62.29 | T85: =IF($C85="","",IF(ISNA(MATCH($C85,Comparativosimulacros!$E:$E,0)),"Falta en Comparativo","Sí está"))
A86: 603 | D86: Escobar Berrio Susana | G86: 3.21 | H86: 2.43 | I86: 3.21 | J86: 3.23 | K86: 2.6 | L86: =IF(OR($A86="",$N86=0),"",COUNTIFS($A$5:$A$1500,$A86,$N$5:$N$1500,">"&$N86)+1) | M86: =IF(OR($A86="",$N86=0),"",IF(AND($A86>=1001,$A86<=1005),COUNTIFS($A$5:$A$1500,">=1001",$A$5:$A$1500,"<=1005",$N$5:$N$1500,">"&$N86)+1,"")) | N86: =ROUND(((O86*3+P86*3+Q86*3+R86*3+S86*1)/13)*5,0) | O86: 46.75 | P86: 35.12 | Q86: 44.25 | R86: 48.13 | S86: 38.33 | T86: =IF($C86="","",IF(ISNA(MATCH($C86,Comparativosimulacros!$E:$E,0)),"Falta en Comparativo","Sí está"))
A87: 603 | D87: Estrada Castro Elieth Camila | G87: 1.7 | H87: 1.21 | I87: 1.6 | J87: 1.47 | K87: 1.62 | L87: =IF(OR($A87="",$N87=0),"",COUNTIFS($A$5:$A$1500,$A87,$N$5:$N$1500,">"&$N87)+1) | M87: =IF(OR($A87="",$N87=0),"",IF(AND($A87>=1001,$A87<=1005),COUNTIFS($A$5:$A$1500,">=1001",$A$5:$A$1500,"<=1005",$N$5:$N$1500,">"&$N87)+1,"")) | N87: =ROUND(((O87*3+P87*3+Q87*3+R87*3+S87*1)/13)*5,0) | O87: 24.75 | P87: 17.56 | Q87: 22.13 | R87: 21.88 | S87: 23.96 | T87: =IF($C87="","",IF(ISNA(MATCH($C87,Comparativosimulacros!$E:$E,0)),"Falta en Comparativo","Sí está"))
A88: 603 | D88: Febres Chaparro Santiago David | G88: 3.21 | H88: 2.53 | I88: 2.47 | J88: 1.47 | K88: 2.92 | L88: =IF(OR($A88="",$N88=0),"",COUNTIFS($A$5:$A$1500,$A88,$N$5:$N$1500,">"&$N88)+1) | M88: =IF(OR($A88="",$N88=0),"",IF(AND($A88>=1001,$A88<=1005),COUNTIFS($A$5:$A$1500,">=1001",$A$5:$A$1500,"<=1005",$N$5:$N$1500,">"&$N88)+1,"")) | N88: =ROUND(((O88*3+P88*3+Q88*3+R88*3+S88*1)/13)*5,0) | O88: 46.75 | P88: 36.61 | Q88: 34.13 | R88: 21.88 | S88: 43.13 | T88: =IF($C88="","",IF(ISNA(MATCH($C88,Comparativosimulacros!$E:$E,0)),"Falta en Comparativo","Sí está"))
A89: 603 | D89: Gonzalez Bedoya Juan Sebastián | G89: 4.54 | H89: 4.63 | I89: 3.86 | J89: 3.82 | K89: 3.57 | L89: =IF(OR($A89="",$N89=0),"",COUNTIFS($A$5:$A$1500,$A89,$N$5:$N$1500,">"&$N89)+1) | M89: =IF(OR($A89="",$N89=0),"",IF(AND($A89>=1001,$A89<=1005),COUNTIFS($A$5:$A$1500,">=1001",$A$5:$A$1500,"<=1005",$N$5:$N$1500,">"&$N89)+1,"")) | N89: =ROUND(((O89*3+P89*3+Q89*3+R89*3+S89*1)/13)*5,0) | O89: 66 | P89: 66.96 | Q89: 53.25 | R89: 56.88 | S89: 52.71 | T89: =IF($C89="","",IF(ISNA(MATCH($C89,Comparativosimulacros!$E:$E,0)),"Falta en Comparativo","Sí está"))
A90: 603 | D90: González Cartagena Mateo | G90: 2.65 | H90: 1.28 | I90: 2.25 | J90: 2.94 | K90: 4.87 | L90: =IF(OR($A90="",$N90=0),"",COUNTIFS($A$5:$A$1500,$A90,$N$5:$N$1500,">"&$N90)+1) | M90: =IF(OR($A90="",$N90=0),"",IF(AND($A90>=1001,$A90<=1005),COUNTIFS($A$5:$A$1500,">=1001",$A$5:$A$1500,"<=1005",$N$5:$N$1500,">"&$N90)+1,"")) | N90: =ROUND(((O90*3+P90*3+Q90*3+R90*3+S90*1)/13)*5,0) | O90: 38.5 | P90: 18.45 | Q90: 31.13 | R90: 43.75 | S90: 71.88 | T90: =IF($C90="","",IF(ISNA(MATCH($C90,Comparativosimulacros!$E:$E,0)),"Falta en Comparativo","Sí está"))
A91: 603 | D91: González Zapata Jonathan Alejandro | G91: 4.16 | H91: 5 | I91: 3.56 | J91: 4.41 | K91: 3.9 | L91: =IF(OR($A91="",$N91=0),"",COUNTIFS($A$5:$A$1500,$A91,$N$5:$N$1500,">"&$N91)+1) | M91: =IF(OR($A91="",$N91=0),"",IF(AND($A91>=1001,$A91<=1005),COUNTIFS($A$5:$A$1500,">=1001",$A$5:$A$1500,"<=1005",$N$5:$N$1500,">"&$N91)+1,"")) | N91: =ROUND(((O91*3+P91*3+Q91*3+R91*3+S91*1)/13)*5,0) | O91: 60.5 | P91: 77.98 | Q91: 49.13 | R91: 65.63 | S91: 57.5 | T91: =IF($C91="","",IF(ISNA(MATCH($C91,Comparativosimulacros!$E:$E,0)),"Falta en Comparativo","Sí está"))
A92: 603 | D92: Guevara Montes Bhianka Juliethe | G92: 2.08 | H92: 1.79 | I92: 1.6 | J92: 3.23 | K92: 1.62 | L92: =IF(OR($A92="",$N92=0),"",COUNTIFS($A$5:$A$1500,$A92,$N$5:$N$1500,">"&$N92)+1) | M92: =IF(OR($A92="",$N92=0),"",IF(AND($A92>=1001,$A92<=1005),COUNTIFS($A$5:$A$1500,">=1001",$A$5:$A$1500,"<=1005",$N$5:$N$1500,">"&$N92)+1,"")) | N92: =ROUND(((O92*3+P92*3+Q92*3+R92*3+S92*1)/13)*5,0) | O92: 30.25 | P92: 25.89 | Q92: 22.13 | R92: 48.13 | S92: 23.96 | T92: =IF($C92="","",IF(ISNA(MATCH($C92,Comparativosimulacros!$E:$E,0)),"Falta en Comparativo","Sí está"))
A93: 603 | D93: Guisao Higuita Guadalupe | G93: 4.35 | H93: 4.22 | I93: 2.69 | J93: 3.82 | K93: 4.55 | L93: =IF(OR($A93="",$N93=0),"",COUNTIFS($A$5:$A$1500,$A93,$N$5:$N$1500,">"&$N93)+1) | M93: =IF(OR($A93="",$N93=0),"",IF(AND($A93>=1001,$A93<=1005),COUNTIFS($A$5:$A$1500,">=1001",$A$5:$A$1500,"<=1005",$N$5:$N$1500,">"&$N93)+1,"")) | N93: =ROUND(((O93*3+P93*3+Q93*3+R93*3+S93*1)/13)*5,0) | O93: 63.25 | P93: 61.01 | Q93: 37.13 | R93: 56.88 | S93: 67.08 | T93: =IF($C93="","",IF(ISNA(MATCH($C93,Comparativosimulacros!$E:$E,0)),"Falta en Comparativo","Sí está"))
A94: 603 | D94: Henao Arteaga Emiliano | G94: 4.35 | H94: 4.22 | I94: 3.64 | J94: 4.11 | K94: 5 | L94: =IF(OR($A94="",$N94=0),"",COUNTIFS($A$5:$A$1500,$A94,$N$5:$N$1500,">"&$N94)+1) | M94: =IF(OR($A94="",$N94=0),"",IF(AND($A94>=1001,$A94<=1005),COUNTIFS($A$5:$A$1500,">=1001",$A$5:$A$1500,"<=1005",$N$5:$N$1500,">"&$N94)+1,"")) | N94: =ROUND(((O94*3+P94*3+Q94*3+R94*3+S94*1)/13)*5,0) | O94: 63.25 | P94: 61.01 | Q94: 50.25 | R94: 61.25 | S94: 76.67 | T94: =IF($C94="","",IF(ISNA(MATCH($C94,Comparativosimulacros!$E:$E,0)),"Falta en Comparativo","Sí está"))
...

Sheet Comparativosimulacros
K1: Primer Simulacro | Y1: Segundo Simulacro | AM1: Comparativo Segundo y Primer Simulacro | BB1: Prueba Saber 11 real aplicada (solo undécimo) | BI1: Estrategias de preparación (solo undécimo) | BM1: Promoción
A2: Perfil Sociodemográfico | K2: Puntaje | T2: Niveles de Desempeño | Y2: Puntaje | AH2: Niveles de Desempeño | AM2: Puntaje y posición (Segundo − Primero) | AV2: Niveles de Desempeño (Segundo − Primero: + subió de nivel) | BB2: Puntaje | BH2: Comparación | BI2: =COUNTIF(BI4:BI1500,"Sí") | BJ2: =COUNTIF(BJ4:BJ1500,"Sí") | BK2: =COUNTIF(BK4:BK1500,"Sí") | BL2: Registro | BM2: =COUNTIF(BM4:BM1500,"Sí")
A3: Diagnóstico | B3: Sede | C3: Grupo | D3: Sexo | E3: Documento | F3: Nombre completo | G3: Primer apellido | H3: Segundo apellido | I3: Primer nombre | J3: Segundo nombre | K3: Puntaje Global | L3: Posición dentro del Respectivo Grupo | M3: Posición dentro del Grado | N3: Posición dentro de Décimos y Undécimos | O3: Matemática | P3: Ciencias Naturales | Q3: Sociales y Ciudadanas | R3: Lectura Crítica | S3: Inglés | T3: Matemática | U3: Ciencias Naturales | V3: Sociales y Ciudadanas | W3: Lectura Crítica | X3: Inglés | Y3: Puntaje Global | Z3: Posición dentro del Respectivo Grupo | AA3: Posición dentro del Grado | AB3: Posición dentro de Décimos y Undécimos | AC3: Matemática | AD3: Ciencias Naturales | AE3: Sociales y Ciudadanas | AF3: Lectura Crítica | AG3: Inglés | AH3: Matemática | AI3: Ciencias Naturales | AJ3: Sociales y Ciudadanas | AK3: Lectura Crítica | AL3: Inglés | AM3: Puntaje Global (Segundo − Primero) | AN3: Cambio de posición en el grupo (− mejoró, + empeoró) | AO3: Cambio de posición en el grado (− mejoró, + empeoró) | AP3: Cambio de posición en décimos y undécimos (− mejoró, + empeoró) | AQ3: Matemática | AR3: Ciencias Naturales | AS3: Sociales y Ciudadanas | AT3: Lectura Crítica | AU3: Inglés | AV3: Matemática | AW3: Ciencias Naturales | AX3: Sociales y Ciudadanas | AY3: Lectura Crítica | AZ3: Inglés | BA3: Comparativo | BB3: Puntaje Global (0–500) | BC3: Matemática | BD3: Ciencias Naturales | BE3: Sociales y Ciudadanas | BF3: Lectura Crítica | BG3: Inglés | BH3: Diferencia Global (Saber 11 real − Segundo Simulacro) | BI3: Preicfes municipal | BJ3: Semestre cero | BK3: Preicfes intensivo | BL3: Otra estrategia / observaciones | BM3: Posible promoción
B4: Bachillerato | C4: 601 | F4: =TRIM(G4&" "&H4&" "&I4&" "&J4) | G4: Acevedo | H4: Castañeda | I4: Luciana | K4: =IF(SUM(O4:S4)=0, "", ROUND(((O4*3+P4*3+Q4*3+R4*3+S4*1)/13)*5,0)) | L4: =IF(OR($C4="",K4=""),"",COUNTIFS($C$4:$C$1500,$C4,K$4:K$1500,">"&K4)+1) | M4: =IF(OR($C4="",K4=""),"",IF(AND($C4>=1001,$C4<=1005),COUNTIFS($C$4:$C$1500,">=1001",$C$4:$C$1500,"<=1005",K$4:K$1500,">"&K4)+1,IF(AND($C4>=1101,$C4<=1105),COUNTIFS($C$4:$C$1500,">=1101",$C$4:$C$1500,"<=1105",K$4:K$1500,">"&K4)+1,IF(AND($C4>=901,$C4<=905),COUNTIFS($C$4:$C$1500,">=901",$C$4:$C$1500,"<=905",K$4:K$1500,">"&K4)+1,IF(AND($C4>=801,$C4<=805),COUNTIFS($C$4:$C$1500,">=801",$C$4:$C$1500,"<=805",K$4:K$1500,">"&K4)+1,IF(AND($C4>=701,$C4<=705),COUNTIFS($C$4:$C$1500,">=701",$C$4:$C$1500,"<=705",K$4:K$1500,">"&K4)+1,IF(AND($C4>=601,$C4<=606),COUNTIFS($C$4:$C$1500,">=601",$C$4:$C$1500,"<=606",K$4:K$1500,">"&K4)+1,""))))))) | N4: =IF(OR($C4="",K4=""),"",IF(OR(AND($C4>=1001,$C4<=1005),AND($C4>=1101,$C4<=1105)),COUNTIFS($C$4:$C$1500,">=1001",$C$4:$C$1500,"<=1005",K$4:K$1500,">"&K4)+COUNTIFS($C$4:$C$1500,">=1101",$C$4:$C$1500,"<=1105",K$4:K$1500,">"&K4)+1,"")) | O4: 26.58 | P4: 55.97 | Q4: 33.61 | R4: 43.13 | S4: 33.54 | T4: =IF(AND(O4>0,O4<36),1,IF(AND(O4>=36,O4<51),2,IF(AND(O4>=51,O4<71),3,IF(AND(O4>=71,O4<=100),4,)))) | U4: =IF(AND(P4>0,P4<41),1,IF(AND(P4>=41,P4<56),2,IF(AND(P4>=56,P4<71),3,IF(AND(P4>=71,P4<=100),4,)))) | V4: =IF(AND(Q4>0,Q4<41),1,IF(AND(Q4>=41,Q4<56),2,IF(AND(Q4>=56,Q4<71),3,IF(AND(Q4>=71,Q4<=100),4,)))) | W4: =IF(AND(R4>0,R4<36),1,IF(AND(R4>=36,R4<51),2,IF(AND(R4>=51,R4<66),3,IF(AND(R4>=66,R4<=100),4,)))) | X4: =IF(AND(S4>0,S4<37),1,IF(AND(S4>=37,S4<58),2,IF(AND(S4>=58,S4<71),3,IF(AND(S4>=71,S4<=100),4,)))) | Y4: =IF(SUM(AC4:AG4)=0, "", ROUND(((AC4*3+AD4*3+AE4*3+AF4*3+AG4*1)/13)*5,0)) | Z4: =IF(OR($C4="",Y4=""),"",COUNTIFS($C$4:$C$1500,$C4,Y$4:Y$1500,">"&Y4)+1) | AA4: =IF(OR($C4="",Y4=""),"",IF(AND($C4>=1001,$C4<=1005),COUNTIFS($C$4:$C$1500,">=1001",$C$4:$C$1500,"<=1005",Y$4:Y$1500,">"&Y4)+1,IF(AND($C4>=1101,$C4<=1105),COUNTIFS($C$4:$C$1500,">=1101",$C$4:$C$1500,"<=1105",Y$4:Y$1500,">"&Y4)+1,IF(AND($C4>=901,$C4<=905),COUNTIFS($C$4:$C$1500,">=901",$C$4:$C$1500,"<=905",Y$4:Y$1500,">"&Y4)+1,IF(AND($C4>=801,$C4<=805),COUNTIFS($C$4:$C$1500,">=801",$C$4:$C$1500,"<=805",Y$4:Y$1500,">"&Y4)+1,IF(AND($C4>=701,$C4<=705),COUNTIFS($C$4:$C$1500,">=701",$C$4:$C$1500,"<=705",Y$4:Y$1500,">"&Y4)+1,IF(AND($C4>=601,$C4<=606),COUNTIFS($C$4:$C$1500,">=601",$C$4:$C$1500,"<=606",Y$4:Y$1500,">"&Y4)+1,""))))))) | AB4: =IF(OR($C4="",Y4=""),"",IF(OR(AND($C4>=1001,$C4<=1005),AND($C4>=1101,$C4<=1105)),COUNTIFS($C$4:$C$1500,">=1001",$C$4:$C$1500,"<=1005",Y$4:Y$1500,">"&Y4)+COUNTIFS($C$4:$C$1500,">=1101",$C$4:$C$1500,"<=1105",Y$4:Y$1500,">"&Y4)+1,"")) | AC4: 44 | AD4: 47.26 | AE4: 52.25 | AF4: 52.5 | AG4: 64.17 | AH4: =IF(AND(AC4>0,AC4<36),1,IF(AND(AC4>=36,AC4<51),2,IF(AND(AC4>=51,AC4<71),3,IF(AND(AC4>=71,AC4<=100),4,)))) | AI4: =IF(AND(AD4>0,AD4<41),1,IF(AND(AD4>=41,AD4<56),2,IF(AND(AD4>=56,AD4<71),3,IF(AND(AD4>=71,AD4<=100),4,)))) | AJ4: =IF(AND(AE4>0,AE4<41),1,IF(AND(AE4>=41,AE4<56),2,IF(AND(AE4>=56,AE4<71),3,IF(AND(AE4>=71,AE4<=100),4,)))) | AK4: =IF(AND(AF4>0,AF4<36),1,IF(AND(AF4>=36,AF4<51),2,IF(AND(AF4>=51,AF4<66),3,IF(AND(AF4>=66,AF4<=100),4,)))) | AL4: =IF(AND(AG4>0,AG4<37),1,IF(AND(AG4>=37,AG4<58),2,IF(AND(AG4>=58,AG4<71),3,IF(AND(AG4>=71,AG4<=100),4,)))) | AM4: =IF((Y4<>"")*(K4<>""),Y4-K4,"") | AN4: =IF((Z4<>"")*(L4<>""),Z4-L4,"") | AO4: =IF((AA4<>"")*(M4<>""),AA4-M4,"") | AP4: =IF((AB4<>"")*(N4<>""),AB4-N4,"") | AQ4: =IF((AC4<>"")*(O4<>""),AC4-O4,"") | AR4: =IF((AD4<>"")*(P4<>""),AD4-P4,"") | AS4: =IF((AE4<>"")*(Q4<>""),AE4-Q4,"") | AT4: =IF((AF4<>"")*(R4<>""),AF4-R4,"") | ... AZ4: =IF((AL4<>"")*(X4<>""),AL4-X4,"") | BA4: =IFERROR(__xludf.dummyfunction("AI(""Actúa como un tutor académico y dirígete personalmente al estudiante "" & I4 & "" "" & J4 & "" "" & G4 & "" "" & H4 & "" hablándole en segunda persona (tú). INSTRUCCIÓN VITAL: A continuación te daré un dato llamado 'Diferencia Global'. Si ese dato es"&"tá vacío o no es un número, significa que el estudiante solo presentó un simulacro; en ese caso, NO hagas comparativos ni hables de evolución, solo redacta un mensaje motivador destacando sus fortalezas y áreas a mejorar basándote en los puntajes del simu"&"lacro que sí presentó. Si la 'Diferencia Global' sí tiene un número, analiza su evolución y su avance o retroceso en el ranking. DATOS DEL ESTUDIANTE -> Diferencia Global: '"" & AM4 & ""'. Diferencias por área: Matemáticas ("" & AQ4 & ""), Ciencias Natura"&"les ("" & AR4 & ""), Sociales ("" & AS4 & ""), Lectura Crítica ("" & AT4 & "") e Inglés ("" & AU4 & ""). Variación en posición: grupo ("" & AN4 & ""), grado ("" & AO4 & "") y media ("" & AP4 & ""). Puntajes Primer Simulacro: Global "" & K4 & "", Mat "" & "&"O4 & "", Cien "" & P4 & "", Soc "" & Q4 & "", Lec "" & R4 & "", Ing "" & S4 & "". Puntajes Segundo Simulacro: Global "" & Y4 & "", Mat "" & AC4 & "", Cien "" & AD4 & "", Soc "" & AE4 & "", Lec "" & AF4 & "", Ing "" & AG4 & "". Escribe un mensaje motivador"&" y breve (máximo 4 líneas)."") "),"=AI(""Actúa como un tutor académico y dirígete personalmente al estudiante "" & I4 & "" "" & J4 & "" "" & G4 & "" "" & H4 & "" hablándole en segunda persona (tú). INSTRUCCIÓN VITAL: A continuación te daré un dato llamado 'Diferencia Global'. Si ese dato e"&"stá vacío o no es un número, significa que el estudiante solo presentó un simulacro; en ese caso, NO hagas comparativos ni hables de evolución, solo redacta un mensaje motivador destacando sus fortalezas y áreas a mejorar basándote en los puntajes del sim"&"ulacro que sí presentó. Si la 'Diferencia Global' sí tiene un número, analiza su evolución y su avance o retroceso en el ranking. DATOS DEL ESTUDIANTE -> Diferencia Global: '"" & AM4 & ""'. Diferencias por área: Matemáticas ("" & AQ4 & ""), Ciencias Natur"&"ales ("" & AR4 & ""), Sociales ("" & AS4 & ""), Lectura Crítica ("" & AT4 & "") e Inglés ("" & AU4 & ""). Variación en posición: grupo ("" & AN4 & ""), grado ("" & AO4 & "") y media ("" & AP4 & ""). Puntajes Primer Simulacro: Global "" & K4 & "", Mat "" &"&" O4 & "", Cien "" & P4 & "", Soc "" & Q4 & "", Lec "" & R4 & "", Ing "" & S4 & "". Puntajes Segundo Simulacro: Global "" & Y4 & "", Mat "" & AC4 & "", Cien "" & AD4 & "", Soc "" & AE4 & "", Lec "" & AF4 & "", Ing "" & AG4 & "". Escribe un mensaje motivado"&"r y breve (máximo 4 líneas)."") ")
B5: Bachillerato | C5: 601 | F5: =TRIM(G5&" "&H5&" "&I5&" "&J5) | G5: Aguiar | H5: García | I5: Jesús | J5: Antonio | K5: =IF(SUM(O5:S5)=0, "", ROUND(((O5*3+P5*3+Q5*3+R5*3+S5*1)/13)*5,0)) | L5: =IF(OR($C5="",K5=""),"",COUNTIFS($C$4:$C$1500,$C5,K$4:K$1500,">"&K5)+1) | M5: =IF(OR($C5="",K5=""),"",IF(AND($C5>=1001,$C5<=1005),COUNTIFS($C$4:$C$1500,">=1001",$C$4:$C$1500,"<=1005",K$4:K$1500,">"&K5)+1,IF(AND($C5>=1101,$C5<=1105),COUNTIFS($C$4:$C$1500,">=1101",$C$4:$C$1500,"<=1105",K$4:K$1500,">"&K5)+1,IF(AND($C5>=901,$C5<=905),COUNTIFS($C$4:$C$1500,">=901",$C$4:$C$1500,"<=905",K$4:K$1500,">"&K5)+1,IF(AND($C5>=801,$C5<=805),COUNTIFS($C$4:$C$1500,">=801",$C$4:$C$1500,"<=805",K$4:K$1500,">"&K5)+1,IF(AND($C5>=701,$C5<=705),COUNTIFS($C$4:$C$1500,">=701",$C$4:$C$1500,"<=705",K$4:K$1500,">"&K5)+1,IF(AND($C5>=601,$C5<=606),COUNTIFS($C$4:$C$1500,">=601",$C$4:$C$1500,"<=606",K$4:K$1500,">"&K5)+1,""))))))) | N5: =IF(OR($C5="",K5=""),"",IF(OR(AND($C5>=1001,$C5<=1005),AND($C5>=1101,$C5<=1105)),COUNTIFS($C$4:$C$1500,">=1001",$C$4:$C$1500,"<=1005",K$4:K$1500,">"&K5)+COUNTIFS($C$4:$C$1500,">=1101",$C$4:$C$1500,"<=1105",K$4:K$1500,">"&K5)+1,"")) | O5: 31.41 | P5: 35.42 | Q5: 21.85 | R5: 47.92 | S5: 28.75 | T5: =IF(AND(O5>0,O5<36),1,IF(AND(O5>=36,O5<51),2,IF(AND(O5>=51,O5<71),3,IF(AND(O5>=71,O5<=100),4,)))) | U5: =IF(AND(P5>0,P5<41),1,IF(AND(P5>=41,P5<56),2,IF(AND(P5>=56,P5<71),3,IF(AND(P5>=71,P5<=100),4,)))) | V5: =IF(AND(Q5>0,Q5<41),1,IF(AND(Q5>=41,Q5<56),2,IF(AND(Q5>=56,Q5<71),3,IF(AND(Q5>=71,Q5<=100),4,)))) | W5: =IF(AND(R5>0,R5<36),1,IF(AND(R5>=36,R5<51),2,IF(AND(R5>=51,R5<66),3,IF(AND(R5>=66,R5<=100),4,)))) | X5: =IF(AND(S5>0,S5<37),1,IF(AND(S5>=37,S5<58),2,IF(AND(S5>=58,S5<71),3,IF(AND(S5>=71,S5<=100),4,)))) | Y5: =IF(SUM(AC5:AG5)=0, "", ROUND(((AC5*3+AD5*3+AE5*3+AF5*3+AG5*1)/13)*5,0)) | Z5: =IF(OR($C5="",Y5=""),"",COUNTIFS($C$4:$C$1500,$C5,Y$4:Y$1500,">"&Y5)+1) | AA5: =IF(OR($C5="",Y5=""),"",IF(AND($C5>=1001,$C5<=1005),COUNTIFS($C$4:$C$1500,">=1001",$C$4:$C$1500,"<=1005",Y$4:Y$1500,">"&Y5)+1,IF(AND($C5>=1101,$C5<=1105),COUNTIFS($C$4:$C$1500,">=1101",$C$4:$C$1500,"<=1105",Y$4:Y$1500,">"&Y5)+1,IF(AND($C5>=901,$C5<=905),COUNTIFS($C$4:$C$1500,">=901",$C$4:$C$1500,"<=905",Y$4:Y$1500,">"&Y5)+1,IF(AND($C5>=801,$C5<=805),COUNTIFS($C$4:$C$1500,">=801",$C$4:$C$1500,"<=805",Y$4:Y$1500,">"&Y5)+1,IF(AND($C5>=701,$C5<=705),COUNTIFS($C$4:$C$1500,">=701",$C$4:$C$1500,"<=705",Y$4:Y$1500,">"&Y5)+1,IF(AND($C5>=601,$C5<=606),COUNTIFS($C$4:$C$1500,">=601",$C$4:$C$1500,"<=606",Y$4:Y$1500,">"&Y5)+1,""))))))) | AB5: =IF(OR($C5="",Y5=""),"",IF(OR(AND($C5>=1001,$C5<=1005),AND($C5>=1101,$C5<=1105)),COUNTIFS($C$4:$C$1500,">=1001",$C$4:$C$1500,"<=1005",Y$4:Y$1500,">"&Y5)+COUNTIFS($C$4:$C$1500,">=1101",$C$4:$C$1500,"<=1105",Y$4:Y$1500,">"&Y5)+1,"")) | AC5: 44 | AD5: 47.26 | AE5: 35.75 | AF5: 35 | AG5: 59.58 | AH5: =IF(AND(AC5>0,AC5<36),1,IF(AND(AC5>=36,AC5<51),2,IF(AND(AC5>=51,AC5<71),3,IF(AND(AC5>=71,AC5<=100),4,)))) | AI5: =IF(AND(AD5>0,AD5<41),1,IF(AND(AD5>=41,AD5<56),2,IF(AND(AD5>=56,AD5<71),3,IF(AND(AD5>=71,AD5<=100),4,)))) | AJ5: =IF(AND(AE5>0,AE5<41),1,IF(AND(AE5>=41,AE5<56),2,IF(AND(AE5>=56,AE5<71),3,IF(AND(AE5>=71,AE5<=100),4,)))) | AK5: =IF(AND(AF5>0,AF5<36),1,IF(AND(AF5>=36,AF5<51),2,IF(AND(AF5>=51,AF5<66),3,IF(AND(AF5>=66,AF5<=100),4,)))) | AL5: =IF(AND(AG5>0,AG5<37),1,IF(AND(AG5>=37,AG5<58),2,IF(AND(AG5>=58,AG5<71),3,IF(AND(AG5>=71,AG5<=100),4,)))) | AM5: =IF((Y5<>"")*(K5<>""),Y5-K5,"") | AN5: =IF((Z5<>"")*(L5<>""),Z5-L5,"") | AO5: =IF((AA5<>"")*(M5<>""),AA5-M5,"") | AP5: =IF((AB5<>"")*(N5<>""),AB5-N5,"") | AQ5: =IF((AC5<>"")*(O5<>""),AC5-O5,"") | AR5: =IF((AD5<>"")*(P5<>""),AD5-P5,"") | AS5: =IF((AE5<>"")*(Q5<>""),AE5-Q5,"") | AT5: =IF((AF5<>"")*(R5<>""),AF5-R5,"") | ... AZ5: =IF((AL5<>"")*(X5<>""),AL5-X5,"") | BA5: =IFERROR(__xludf.dummyfunction("AI(""Actúa como un tutor académico y dirígete personalmente al estudiante "" & I5 & "" "" & J5 & "" "" & G5 & "" "" & H5 & "" hablándole en segunda persona (tú). INSTRUCCIÓN VITAL: A continuación te daré un dato llamado 'Diferencia Global'. Si ese dato es"&"tá vacío o no es un número, significa que el estudiante solo presentó un simulacro; en ese caso, NO hagas comparativos ni hables de evolución, solo redacta un mensaje motivador destacando sus fortalezas y áreas a mejorar basándote en los puntajes del simu"&"lacro que sí presentó. Si la 'Diferencia Global' sí tiene un número, analiza su evolución y su avance o retroceso en el ranking. DATOS DEL ESTUDIANTE -> Diferencia Global: '"" & AM5 & ""'. Diferencias por área: Matemáticas ("" & AQ5 & ""), Ciencias Natura"&"les ("" & AR5 & ""), Sociales ("" & AS5 & ""), Lectura Crítica ("" & AT5 & "") e Inglés ("" & AU5 & ""). Variación en posición: grupo ("" & AN5 & ""), grado ("" & AO5 & "") y media ("" & AP5 & ""). Puntajes Primer Simulacro: Global "" & K5 & "", Mat "" & "&"O4 & "", Cien "" & P5 & "", Soc "" & Q5 & "", Lec "" & R5 & "", Ing "" & S5 & "". Puntajes Segundo Simulacro: Global "" & Y5 & "", Mat "" & AC5 & "", Cien "" & AD5 & "", Soc "" & AE5 & "", Lec "" & AF5 & "", Ing "" & AG5 & "". Escribe un mensaje motivador"&" y breve (máximo 4 líneas)."") "),"=AI(""Actúa como un tutor académico y dirígete personalmente al estudiante "" & I5 & "" "" & J5 & "" "" & G5 & "" "" & H5 & "" hablándole en segunda persona (tú). INSTRUCCIÓN VITAL: A continuación te daré un dato llamado 'Diferencia Global'. Si ese dato e"&"stá vacío o no es un número, significa que el estudiante solo presentó un simulacro; en ese caso, NO hagas comparativos ni hables de evolución, solo redacta un mensaje motivador destacando sus fortalezas y áreas a mejorar basándote en los puntajes del sim"&"ulacro que sí presentó. Si la 'Diferencia Global' sí tiene un número, analiza su evolución y su avance o retroceso en el ranking. DATOS DEL ESTUDIANTE -> Diferencia Global: '"" & AM5 & ""'. Diferencias por área: Matemáticas ("" & AQ5 & ""), Ciencias Natur"&"ales ("" & AR5 & ""), Sociales ("" & AS5 & ""), Lectura Crítica ("" & AT5 & "") e Inglés ("" & AU5 & ""). Variación en posición: grupo ("" & AN5 & ""), grado ("" & AO5 & "") y media ("" & AP5 & ""). Puntajes Primer Simulacro: Global "" & K5 & "", Mat "" &"&" O5 & "", Cien "" & P5 & "", Soc "" & Q5 & "", Lec "" & R5 & "", Ing "" & S5 & "". Puntajes Segundo Simulacro: Global "" & Y5 & "", Mat "" & AC5 & "", Cien "" & AD5 & "", Soc "" & AE5 & "", Lec "" & AF5 & "", Ing "" & AG5 & "". Escribe un mensaje motivado"&"r y breve (máximo 4 líneas)."") ")
B6: Bachillerato | C6: 601 | F6: =TRIM(G6&" "&H6&" "&I6&" "&J6) | G6: Alcaraz | H6: Londoño | I6: Jean | J6: Pool | K6: =IF(SUM(O6:S6)=0, "", ROUND(((O6*3+P6*3+Q6*3+R6*3+S6*1)/13)*5,0)) | L6: =IF(OR($C6="",K6=""),"",COUNTIFS($C$4:$C$1500,$C6,K$4:K$1500,">"&K6)+1) | M6: =IF(OR($C6="",K6=""),"",IF(AND($C6>=1001,$C6<=1005),COUNTIFS($C$4:$C$1500,">=1001",$C$4:$C$1500,"<=1005",K$4:K$1500,">"&K6)+1,IF(AND($C6>=1101,$C6<=1105),COUNTIFS($C$4:$C$1500,">=1101",$C$4:$C$1500,"<=1105",K$4:K$1500,">"&K6)+1,IF(AND($C6>=901,$C6<=905),COUNTIFS($C$4:$C$1500,">=901",$C$4:$C$1500,"<=905",K$4:K$1500,">"&K6)+1,IF(AND($C6>=801,$C6<=805),COUNTIFS($C$4:$C$1500,">=801",$C$4:$C$1500,"<=805",K$4:K$1500,">"&K6)+1,IF(AND($C6>=701,$C6<=705),COUNTIFS($C$4:$C$1500,">=701",$C$4:$C$1500,"<=705",K$4:K$1500,">"&K6)+1,IF(AND($C6>=601,$C6<=606),COUNTIFS($C$4:$C$1500,">=601",$C$4:$C$1500,"<=606",K$4:K$1500,">"&K6)+1,""))))))) | N6: =IF(OR($C6="",K6=""),"",IF(OR(AND($C6>=1001,$C6<=1005),AND($C6>=1101,$C6<=1105)),COUNTIFS($C$4:$C$1500,">=1001",$C$4:$C$1500,"<=1005",K$4:K$1500,">"&K6)+COUNTIFS($C$4:$C$1500,">=1101",$C$4:$C$1500,"<=1105",K$4:K$1500,">"&K6)+1,"")) | O6: 46.39 | P6: 44.72 | Q6: 39.5 | R6: 43.13 | S6: 62.29 | T6: =IF(AND(O6>0,O6<36),1,IF(AND(O6>=36,O6<51),2,IF(AND(O6>=51,O6<71),3,IF(AND(O6>=71,O6<=100),4,)))) | U6: =IF(AND(P6>0,P6<41),1,IF(AND(P6>=41,P6<56),2,IF(AND(P6>=56,P6<71),3,IF(AND(P6>=71,P6<=100),4,)))) | V6: =IF(AND(Q6>0,Q6<41),1,IF(AND(Q6>=41,Q6<56),2,IF(AND(Q6>=56,Q6<71),3,IF(AND(Q6>=71,Q6<=100),4,)))) | W6: =IF(AND(R6>0,R6<36),1,IF(AND(R6>=36,R6<51),2,IF(AND(R6>=51,R6<66),3,IF(AND(R6>=66,R6<=100),4,)))) | X6: =IF(AND(S6>0,S6<37),1,IF(AND(S6>=37,S6<58),2,IF(AND(S6>=58,S6<71),3,IF(AND(S6>=71,S6<=100),4,)))) | Y6: =IF(SUM(AC6:AG6)=0, "", ROUND(((AC6*3+AD6*3+AE6*3+AF6*3+AG6*1)/13)*5,0)) | Z6: =IF(OR($C6="",Y6=""),"",COUNTIFS($C$4:$C$1500,$C6,Y$4:Y$1500,">"&Y6)+1) | AA6: =IF(OR($C6="",Y6=""),"",IF(AND($C6>=1001,$C6<=1005),COUNTIFS($C$4:$C$1500,">=1001",$C$4:$C$1500,"<=1005",Y$4:Y$1500,">"&Y6)+1,IF(AND($C6>=1101,$C6<=1105),COUNTIFS($C$4:$C$1500,">=1101",$C$4:$C$1500,"<=1105",Y$4:Y$1500,">"&Y6)+1,IF(AND($C6>=901,$C6<=905),COUNTIFS($C$4:$C$1500,">=901",$C$4:$C$1500,"<=905",Y$4:Y$1500,">"&Y6)+1,IF(AND($C6>=801,$C6<=805),COUNTIFS($C$4:$C$1500,">=801",$C$4:$C$1500,"<=805",Y$4:Y$1500,">"&Y6)+1,IF(AND($C6>=701,$C6<=705),COUNTIFS($C$4:$C$1500,">=701",$C$4:$C$1500,"<=705",Y$4:Y$1500,">"&Y6)+1,IF(AND($C6>=601,$C6<=606),COUNTIFS($C$4:$C$1500,">=601",$C$4:$C$1500,"<=606",Y$4:Y$1500,">"&Y6)+1,""))))))) | AB6: =IF(OR($C6="",Y6=""),"",IF(OR(AND($C6>=1001,$C6<=1005),AND($C6>=1101,$C6<=1105)),COUNTIFS($C$4:$C$1500,">=1001",$C$4:$C$1500,"<=1005",Y$4:Y$1500,">"&Y6)+COUNTIFS($C$4:$C$1500,">=1101",$C$4:$C$1500,"<=1105",Y$4:Y$1500,">"&Y6)+1,"")) | AC6: 52.25 | AD6: 60.95 | AE6: 35.75 | AF6: 39.38 | AG6: 68.75 | AH6: =IF(AND(AC6>0,AC6<36),1,IF(AND(AC6>=36,AC6<51),2,IF(AND(AC6>=51,AC6<71),3,IF(AND(AC6>=71,AC6<=100),4,)))) | AI6: =IF(AND(AD6>0,AD6<41),1,IF(AND(AD6>=41,AD6<56),2,IF(AND(AD6>=56,AD6<71),3,IF(AND(AD6>=71,AD6<=100),4,)))) | AJ6: =IF(AND(AE6>0,AE6<41),1,IF(AND(AE6>=41,AE6<56),2,IF(AND(AE6>=56,AE6<71),3,IF(AND(AE6>=71,AE6<=100),4,)))) | AK6: =IF(AND(AF6>0,AF6<36),1,IF(AND(AF6>=36,AF6<51),2,IF(AND(AF6>=51,AF6<66),3,IF(AND(AF6>=66,AF6<=100),4,)))) | AL6: =IF(AND(AG6>0,AG6<37),1,IF(AND(AG6>=37,AG6<58),2,IF(AND(AG6>=58,AG6<71),3,IF(AND(AG6>=71,AG6<=100),4,)))) | AM6: =IF((Y6<>"")*(K6<>""),Y6-K6,"") | AN6: =IF((Z6<>"")*(L6<>""),Z6-L6,"") | AO6: =IF((AA6<>"")*(M6<>""),AA6-M6,"") | AP6: =IF((AB6<>"")*(N6<>""),AB6-N6,"") | AQ6: =IF((AC6<>"")*(O6<>""),AC6-O6,"") | AR6: =IF((AD6<>"")*(P6<>""),AD6-P6,"") | AS6: =IF((AE6<>"")*(Q6<>""),AE6-Q6,"") | AT6: =IF((AF6<>"")*(R6<>""),AF6-R6,"") | ... AZ6: =IF((AL6<>"")*(X6<>""),AL6-X6,"") | BA6: =IFERROR(__xludf.dummyfunction("AI(""Actúa como un tutor académico y dirígete personalmente al estudiante "" & I6 & "" "" & J6 & "" "" & G6 & "" "" & H6 & "" hablándole en segunda persona (tú). INSTRUCCIÓN VITAL: A continuación te daré un dato llamado 'Diferencia Global'. Si ese dato es"&"tá vacío o no es un número, significa que el estudiante solo presentó un simulacro; en ese caso, NO hagas comparativos ni hables de evolución, solo redacta un mensaje motivador destacando sus fortalezas y áreas a mejorar basándote en los puntajes del simu"&"lacro que sí presentó. Si la 'Diferencia Global' sí tiene un número, analiza su evolución y su avance o retroceso en el ranking. DATOS DEL ESTUDIANTE -> Diferencia Global: '"" & AM6 & ""'. Diferencias por área: Matemáticas ("" & AQ6 & ""), Ciencias Natura"&"les ("" & AR6 & ""), Sociales ("" & AS6 & ""), Lectura Crítica ("" & AT6 & "") e Inglés ("" & AU6 & ""). Variación en posición: grupo ("" & AN6 & ""), grado ("" & AO6 & "") y media ("" & AP6 & ""). Puntajes Primer Simulacro: Global "" & K6 & "", Mat "" & "&"O4 & "", Cien "" & P6 & "", Soc "" & Q6 & "", Lec "" & R6 & "", Ing "" & S6 & "". Puntajes Segundo Simulacro: Global "" & Y6 & "", Mat "" & AC6 & "", Cien "" & AD6 & "", Soc "" & AE6 & "", Lec "" & AF6 & "", Ing "" & AG6 & "". Escribe un mensaje motivador"&" y breve (máximo 4 líneas)."") "),"=AI(""Actúa como un tutor académico y dirígete personalmente al estudiante "" & I6 & "" "" & J6 & "" "" & G6 & "" "" & H6 & "" hablándole en segunda persona (tú). INSTRUCCIÓN VITAL: A continuación te daré un dato llamado 'Diferencia Global'. Si ese dato e"&"stá vacío o no es un número, significa que el estudiante solo presentó un simulacro; en ese caso, NO hagas comparativos ni hables de evolución, solo redacta un mensaje motivador destacando sus fortalezas y áreas a mejorar basándote en los puntajes del sim"&"ulacro que sí presentó. Si la 'Diferencia Global' sí tiene un número, analiza su evolución y su avance o retroceso en el ranking. DATOS DEL ESTUDIANTE -> Diferencia Global: '"" & AM6 & ""'. Diferencias por área: Matemáticas ("" & AQ6 & ""), Ciencias Natur"&"ales ("" & AR6 & ""), Sociales ("" & AS6 & ""), Lectura Crítica ("" & AT6 & "") e Inglés ("" & AU6 & ""). Variación en posición: grupo ("" & AN6 & ""), grado ("" & AO6 & "") y media ("" & AP6 & ""). Puntajes Primer Simulacro: Global "" & K6 & "", Mat "" &"&" O6 & "", Cien "" & P6 & "", Soc "" & Q6 & "", Lec "" & R6 & "", Ing "" & S6 & "". Puntajes Segundo Simulacro: Global "" & Y6 & "", Mat "" & AC6 & "", Cien "" & AD6 & "", Soc "" & AE6 & "", Lec "" & AF6 & "", Ing "" & AG6 & "". Escribe un mensaje motivado"&"r y breve (máximo 4 líneas)."") ")
